<?xml version="1.0" ?>
<!-- =================================================================================== -->
<!-- |    This document was autogenerated by xacro from basic_mobile_robot.urdf        | -->
<!-- |    EDITING THIS FILE BY HAND IS NOT RECOMMENDED                                 | -->
<!-- =================================================================================== -->
<robot name="basic_mobile_robot">
  <!-- ****************** ROBOT BASE FOOTPRINT ***************************  -->
  <link name="base_footprint"/>
  <joint name="base_joint" type="fixed">
    <parent link="base_footprint"/>
    <child link="base_link"/>
    <origin rpy="0 0 0" xyz="0.0 0.0 0.19"/>
  </joint>
  <!-- ********************** ROBOT BASE *********************************  -->
  <link name="base_link">
    <visual>
      <origin rpy="1.5707963267949 0 3.141592654" xyz="0 0 -0.05"/>
      <geometry>
        <mesh filename="package://basic_mobile_robot/meshes/robot_base.stl"/>
      </geometry>
      <material name="Red">
        <color rgba="1.0 0.0 0.0 1.0"/>
      </material>
    </visual>
    <collision>
      <geometry>
        <box size="0.7 0.39 0.2"/>
      </geometry>
    </collision>
    <inertial>
      <origin rpy="1.5707963267948966 0 1.5707963267948966" xyz="0 0 0"/>
      <mass value="40.0"/>
      <inertia ixx="1.7666666666666664" ixy="0.0" ixz="0.0" iyy="2.140333333333333" iyz="0.0" izz="0.6403333333333334"/>
    </inertial>
  </link>
  <gazebo reference="base_link">
    <material>Gazebo/Red</material>
  </gazebo>
  <link name="drivewhl_l_link">
    <visual>
      <origin rpy="1.5707963267949 0 0" xyz="0 0 0"/>
      <geometry>
        <cylinder length="0.06" radius="0.14"/>
      </geometry>
      <material name="White">
        <color rgba="1.0 1.0 1.0 1.0"/>
      </material>
    </visual>
    <collision>
      <origin rpy="1.5707963267948966 0 0" xyz="0 0 0"/>
      <geometry>
        <cylinder length="0.06" radius="0.14"/>
      </geometry>
    </collision>
    <inertial>
      <origin rpy="1.5707963267948966 0 0" xyz="0 0 0"/>
      <mass value="110.5"/>
      <inertia ixx="0.5746000000000001" ixy="0" ixz="0" iyy="0.5746000000000001" iyz="0" izz="1.0829000000000002"/>
    </inertial>
  </link>
  <joint name="drivewhl_l_joint" type="revolute">
    <parent link="base_link"/>
    <child link="drivewhl_l_link"/>
    <origin rpy="0 0 0" xyz="-0.221 0.23 -0.05"/>
    <limit effort="30" lower="-3.1415" upper="3.1415" velocity="5.0"/>
    <axis xyz="0 1 0"/>
  </joint>
  <link name="drivewhl_r_link">
    <visual>
      <origin rpy="1.5707963267949 0 0" xyz="0 0 0"/>
      <geometry>
        <cylinder length="0.06" radius="0.14"/>
      </geometry>
      <material name="White">
        <color rgba="1.0 1.0 1.0 1.0"/>
      </material>
    </visual>
    <collision>
      <origin rpy="1.5707963267948966 0 0" xyz="0 0 0"/>
      <geometry>
        <cylinder length="0.06" radius="0.14"/>
      </geometry>
    </collision>
    <inertial>
      <origin rpy="1.5707963267948966 0 0" xyz="0 0 0"/>
      <mass value="110.5"/>
      <inertia ixx="0.5746000000000001" ixy="0" ixz="0" iyy="0.5746000000000001" iyz="0" izz="1.0829000000000002"/>
    </inertial>
  </link>
  <joint name="drivewhl_r_joint" type="revolute">
    <parent link="base_link"/>
    <child link="drivewhl_r_link"/>
    <origin rpy="0 0 0" xyz="-0.221 -0.23 -0.05"/>
    <limit effort="30" lower="-3.1415" upper="3.1415" velocity="5.0"/>
    <axis xyz="0 1 0"/>
  </joint>
  <!-- *********************** CASTER WHEEL ******************************  -->
  <link name="front_caster">
    <visual>
      <geometry>
        <sphere radius="0.09"/>
      </geometry>
      <material name="White">
        <color rgba="1.0 1.0 1.0 1.0"/>
      </material>
    </visual>
    <collision>
      <origin rpy="0 0 0" xyz="0 0 0"/>
      <geometry>
        <sphere radius="0.09"/>
      </geometry>
    </collision>
    <inertial>
      <mass value="10.05"/>
      <inertia ixx="0.032562" ixy="0.0" ixz="0.0" iyy="0.032562" iyz="0.0" izz="0.032562"/>
    </inertial>
  </link>
  <gazebo reference="front_caster">
    <mu1>0.01</mu1>
    <mu2>0.01</mu2>
    <material>Gazebo/White</material>
  </gazebo>
  <joint name="caster_joint" type="fixed">
    <parent link="base_link"/>
    <child link="front_caster"/>
    <origin rpy="0 0 0" xyz="0.217 0.0 -0.1"/>
  </joint>
  <!-- *********************** IMU SETUP *********************************  -->
  <joint name="imu_joint" type="fixed">
    <parent link="base_link"/>
    <child link="imu_link"/>
    <origin rpy="0 0 0" xyz="-0.10 0 0.05"/>
  </joint>
  <link name="imu_link"/>
  <!-- *********************** GPS SETUP **********************************  -->
  <joint name="gps_joint" type="fixed">
    <parent link="base_link"/>
    <child link="gps_link"/>
    <origin rpy="0 0 0" xyz="0.10 0 0.05"/>
  </joint>
  <link name="gps_link"/>
</robot>
